Workbook

Sheet RESULTADOS MES
A1: PLANTILLA INFORME MES
A3: AREA | C3: RUBRO | D3: RESULTADO MES | H3: ACUMULADO
D4: N° | E4: VALOR | F4: % | G4: PROMEDIO | H4: N° | I4: VALOR | J4: % | K4: PROMEDIO
A5: VENTAS | B5: VENTA | C5: Ventas Procesables | D5: =+Ventas!B2 -> 0 | E5: =+Ventas!C2 -> 0 | F5: =+E5/$E$8 -> #DIV/0! | G5: =+E5/D5 -> #DIV/0! | H5: =+Ventas!D2 -> 0 | I5: =+Ventas!E2 -> 0 | J5: =+I5/$I$8 -> #DIV/0! | K5: =+I5/H5 -> #DIV/0!
C6: Ventas No Procesables con Rcdo | D6: =+Ventas!B3 -> 0 | E6: =+Ventas!C3 -> 0 | F6: =+E6/$E$8 -> #DIV/0! | G6: =+E6/D6 -> #DIV/0! | H6: =+Ventas!D3 -> 0 | I6: =+Ventas!E3 -> 0 | J6: =+I6/$I$8 -> #DIV/0! | K6: =+I6/H6 -> #DIV/0!
C7: Ventas No Procesables sin Recaudo | D7: =+Ventas!B4 -> 0 | E7: =+Ventas!C4 -> 0 | F7: =+E7/$E$8 -> #DIV/0! | G7: =+E7/D7 -> #DIV/0! | H7: =+Ventas!D4 -> 0 | I7: =+Ventas!E4 -> 0 | J7: =+I7/$I$8 -> #DIV/0! | K7: =+I7/H7 -> #DIV/0!
C8: TOTAL VENTAS DEL MES | D8: =SUM(D5:D7) -> 0 | E8: =SUM(E5:E7) -> 0 | F8: =SUM(F5:F7) -> #DIV/0! | G8: =+E8/D8 -> #DIV/0! | H8: =SUM(H5:H7) -> 0 | I8: =SUM(I5:I7) -> 0 | J8: =SUM(J5:J7) -> #DIV/0! | K8: =+I8/H8 -> #DIV/0!
B9: RECAUDO | C9: RECAUDOS | D9: N° | E9: VALOR | F9: % | G9: % DE VENTAS | H9: N° | I9: VALOR | J9: % | K9: % DE VENTAS
C10: Plata en Mesa | D10: =+Ventas!B5 -> 0 | E10: =+Ventas!C5 -> 0 | F10: =+E10/$E$12 -> #DIV/0! | G10: =+E10/E5 -> #DIV/0! | H10: =+Ventas!D5 -> 0 | I10: =+Ventas!E5 -> 0 | J10: =+I10/$I$12 -> #DIV/0! | K10: =+I10/I8 -> #DIV/0!
C11: Plata en Mes | D11: =+Ventas!B6 -> 0 | E11: =+Ventas!C6 -> 0 | F11: =+E11/$E$12 -> #DIV/0! | G11: =+E11/E5 -> #DIV/0! | H11: =+Ventas!D6 -> 0 | I11: =+Ventas!E6 -> 0 | J11: =+I11/$I$12 -> #DIV/0! | K11: =+I11/I8 -> #DIV/0!
C12: Recaudo por ventas del mes | D12: =+Ventas!B7 -> 0 | E12: =+Ventas!C7 -> 0 | F12: =+E12/$E$12 -> #DIV/0! | G12: =+E12/E5 -> #DIV/0! | H12: =+Ventas!D7 -> 0 | I12: =SUM(I9:I11) -> 0 | J12: =SUM(J9:J11) -> #DIV/0! | K12: =+I12/I8 -> #DIV/0!
B13: TOTALES | C13: ADJUDICACIONES | D13: N° | E13: VALOR | F13: % | G13: PROMEDIO | H13: N° | I13: VALOR | J13: % | K13: PROMEDIO
C14: Ventas | D14: =+D8 -> 0 | E14: =+E8 -> 0 | F14: =+D14/$D$17 -> #DIV/0! | G14: =+E14/D14 -> #DIV/0! | H14: =+H8 -> 0 | I14: =+I8 -> 0 | J14: =+H14/$H$17 -> #DIV/0! | K14: =+I14/H14 -> #DIV/0!
C15: Novaciones | D15: =+Ventas!B9 -> 0 | E15: =+Ventas!C9 -> 0 | F15: =+D15/$D$17 -> #DIV/0! | G15: =+E15/D15 -> #DIV/0! | H15: =+Ventas!D9 -> 0 | I15: =+Ventas!E9 -> 0 | J15: =+H15/$H$17 -> #DIV/0! | K15: =+I15/H15 -> #DIV/0!
C16: Canjes | D16: =+Ventas!B10 -> 0 | E16: =+Ventas!C10 -> 0 | F16: =+D16/$D$17 -> #DIV/0! | G16: =+E16/D16 -> #DIV/0! | H16: =+Ventas!D10 -> 0 | I16: =+Ventas!E10 -> 0 | J16: =+H16/$H$17 -> #DIV/0! | K16: =+I16/H16 -> #DIV/0!
C17: TOTAL ADJUDICACIONES | D17: =+D8+D15+D16 -> 0 | E17: =+E8+E18+E15+E16 -> 0 | F17: =+SUM(F14:F16) -> #DIV/0! | G17: =+E17/D17 -> #DIV/0! | H17: =+H8+H15+H16 -> 0 | I17: =+I8+I18+I15+I16 -> 0 | J17: =+SUM(J14:J16) -> #DIV/0! | K17: =+I17/H17 -> #DIV/0!
C18: Desistidos | D18: =+Ventas!B8 -> 0 | E18: =+Ventas!C8 -> 0 | F18: =+D18/($D$17+D18) -> #DIV/0! | G18: =+E18/D18 -> #DIV/0! | H18: =+Ventas!D8 -> 0 | I18: =+Ventas!E8 -> 0 | J18: =+H18/($H$17+H18) -> #DIV/0! | K18: =+I18/H18 -> #DIV/0!
A19: CARTERA | B19: CARTERA COMERCIAL | D19: MES ACTUAL | F19: RECAUDO | H19: CUMPLIMIENTO | J19: SIGUIENTE MES
D20: N° | E20: VALOR | F20: N° | G20: VALOR | H20: N° | I20: VALOR | J20: N° | K20: VALOR
C21: Del mes | D21: =+COUNTIFS(Cartera!E:E,"Comercial",Cartera!F:F,'RESULTADOS MES'!C23,Cartera!G:G,">0") -> 0 | E21: =SUMIFS(Cartera!G:G,Cartera!E:E,"Comercial",Cartera!F:F,'RESULTADOS MES'!C23,Cartera!G:G,">0") -> 0 | F21: =+COUNTIFS(Cartera!E:E,"Comercial",Cartera!F:F,'RESULTADOS MES'!C23,Cartera!H:H,">0") -> 0 | G21: =+SUMIFS(Cartera!H:H,Cartera!E:E,"Comercial",Cartera!F:F,'RESULTADOS MES'!C23,Cartera!H:H,">0") -> 0 | H21: =+F21/D21 -> #DIV/0! | I21: =+G21/E21 -> #DIV/0! | J21: =COUNTIFS(PptoSiguiente!E:E,"Comercial",PptoSiguiente!F:F,'RESULTADOS MES'!C23,PptoSiguiente!G:G,">0") -> 0 | K21: =SUMIFS(PptoSiguiente!G:G,PptoSiguiente!E:E,"Comercial",PptoSiguiente!F:F,'RESULTADOS MES'!C23,PptoSiguiente!G:G,">0") -> 0
C22: Vencido | D22: =+COUNTIFS(Cartera!E:E,"Comercial",Cartera!F:F,'RESULTADOS MES'!C23,Cartera!I:I,">0") -> 0 | E22: =SUMIFS(Cartera!I:I,Cartera!E:E,"Comercial",Cartera!F:F,'RESULTADOS MES'!C23,Cartera!I:I,">0") -> 0 | F22: =+COUNTIFS(Cartera!E:E,"Comercial",Cartera!F:F,'RESULTADOS MES'!C23,Cartera!J:J,">0") -> 0 | G22: =+SUMIFS(Cartera!J:J,Cartera!E:E,"Comercial",Cartera!F:F,'RESULTADOS MES'!C23,Cartera!J:J,">0") -> 0 | H22: =+F22/D22 -> #DIV/0! | I22: =+G22/E22 -> #DIV/0! | J22: =+COUNTIFS(PptoSiguiente!E:E,"Comercial",PptoSiguiente!F:F,'RESULTADOS MES'!C23,PptoSiguiente!I:I,">0") -> 0 | K22: =SUMIFS(PptoSiguiente!I:I,PptoSiguiente!E:E,"Comercial",PptoSiguiente!F:F,'RESULTADOS MES'!C23,PptoSiguiente!I:I,">0") -> 0
C23: -30-30 | D23: =+COUNTIFS(Cartera!E:E,"Comercial",Cartera!F:F,'RESULTADOS MES'!C23,Cartera!K:K,">0") -> 0 | E23: =+SUBTOTAL(9,E21:E22) -> 0 | F23: =+COUNTIFS(Cartera!E:E,"Comercial",Cartera!F:F,'RESULTADOS MES'!C23,Cartera!L:L,">0") -> 0 | G23: =+SUBTOTAL(9,G21:G22) -> 0 | H23: =+F23/D23 -> #DIV/0! | I23: =+G23/E23 -> #DIV/0! | J23: =+COUNTIFS(PptoSiguiente!E:E,"Comercial",PptoSiguiente!F:F,'RESULTADOS MES'!C23,PptoSiguiente!K:K,">0") -> 0 | K23: =+SUBTOTAL(9,K21:K22) -> 0
C24: Del mes | D24: =+COUNTIFS(Cartera!E:E,"Comercial",Cartera!F:F,'RESULTADOS MES'!C26,Cartera!G:G,">0") -> 0 | E24: =SUMIFS(Cartera!G:G,Cartera!E:E,"Comercial",Cartera!F:F,'RESULTADOS MES'!C26,Cartera!G:G,">0") -> 0 | F24: =+COUNTIFS(Cartera!E:E,"Comercial",Cartera!F:F,'RESULTADOS MES'!C26,Cartera!H:H,">0") -> 0 | G24: =+SUMIFS(Cartera!H:H,Cartera!E:E,"Comercial",Cartera!F:F,'RESULTADOS MES'!C26,Cartera!H:H,">0") -> 0 | H24: =+F24/D24 -> #DIV/0! | I24: =+G24/E24 -> #DIV/0! | J24: =+COUNTIFS(PptoSiguiente!E:E,"Comercial",PptoSiguiente!F:F,'RESULTADOS MES'!C26,PptoSiguiente!G:G,">0") -> 0 | K24: =SUMIFS(PptoSiguiente!G:G,PptoSiguiente!E:E,"Comercial",PptoSiguiente!F:F,'RESULTADOS MES'!C26,PptoSiguiente!G:G,">0") -> 0
C25: Vencido | D25: =+COUNTIFS(Cartera!E:E,"Comercial",Cartera!F:F,'RESULTADOS MES'!C26,Cartera!I:I,">0") -> 0 | E25: =SUMIFS(Cartera!I:I,Cartera!E:E,"Comercial",Cartera!F:F,'RESULTADOS MES'!C26,Cartera!I:I,">0") -> 0 | F25: =+COUNTIFS(Cartera!E:E,"Comercial",Cartera!F:F,'RESULTADOS MES'!C26,Cartera!J:J,">0") -> 0 | G25: =+SUMIFS(Cartera!J:J,Cartera!E:E,"Comercial",Cartera!F:F,'RESULTADOS MES'!C26,Cartera!J:J,">0") -> 0 | H25: =+F25/D25 -> #DIV/0! | I25: =+G25/E25 -> #DIV/0! | J25: =+COUNTIFS(PptoSiguiente!E:E,"Comercial",PptoSiguiente!F:F,'RESULTADOS MES'!C26,PptoSiguiente!I:I,">0") -> 0 | K25: =SUMIFS(PptoSiguiente!I:I,PptoSiguiente!E:E,"Comercial",PptoSiguiente!F:F,'RESULTADOS MES'!C26,PptoSiguiente!I:I,">0") -> 0
C26: 30-60 | D26: =+COUNTIFS(Cartera!E:E,"Comercial",Cartera!F:F,'RESULTADOS MES'!C26,Cartera!K:K,">0") -> 0 | E26: =+SUBTOTAL(9,E24:E25) -> 0 | F26: =+COUNTIFS(Cartera!E:E,"Comercial",Cartera!F:F,'RESULTADOS MES'!C26,Cartera!L:L,">0") -> 0 | G26: =+SUBTOTAL(9,G24:G25) -> 0 | H26: =+F26/D26 -> #DIV/0! | I26: =+G26/E26 -> #DIV/0! | J26: =+COUNTIFS(PptoSiguiente!E:E,"Comercial",PptoSiguiente!F:F,'RESULTADOS MES'!C26,PptoSiguiente!K:K,">0") -> 0 | K26: =+SUBTOTAL(9,K24:K25) -> 0
C27: Del mes | D27: =+COUNTIFS(Cartera!E:E,"Comercial",Cartera!F:F,'RESULTADOS MES'!C29,Cartera!G:G,">0",Cartera!C:C,"Aprobado") -> 0 | E27: =SUMIFS(Cartera!G:G,Cartera!E:E,"Comercial",Cartera!F:F,'RESULTADOS MES'!C29,Cartera!G:G,">0",Cartera!C:C,"Aprobado") -> 0 | F27: =+COUNTIFS(Cartera!E:E,"Comercial",Cartera!F:F,'RESULTADOS MES'!C29,Cartera!H:H,">0",Cartera!C:C,"Aprobado") -> 0 | G27: =+SUMIFS(Cartera!H:H,Cartera!E:E,"Comercial",Cartera!F:F,'RESULTADOS MES'!C29,Cartera!H:H,">0",Cartera!C:C,"Aprobado") -> 0 | H27: =+F27/D27 -> #DIV/0! | I27: =+G27/E27 -> #DIV/0! | J27: =+COUNTIFS(PptoSiguiente!E:E,"Comercial",PptoSiguiente!F:F,'RESULTADOS MES'!C29,PptoSiguiente!G:G,">0",Cartera!C:C,"Aprobado") -> 0 | K27: =SUMIFS(PptoSiguiente!G:G,PptoSiguiente!E:E,"Comercial",PptoSiguiente!F:F,'RESULTADOS MES'!C29,PptoSiguiente!G:G,">0",Cartera!C:C,"Aprobado") -> 0
C28: Vencido | D28: =+COUNTIFS(Cartera!E:E,"Comercial",Cartera!F:F,'RESULTADOS MES'!C29,Cartera!I:I,">0",Cartera!C:C,"Aprobado") -> 0 | E28: =SUMIFS(Cartera!I:I,Cartera!E:E,"Comercial",Cartera!F:F,'RESULTADOS MES'!C29,Cartera!I:I,">0",Cartera!C:C,"Aprobado") -> 0 | F28: =+COUNTIFS(Cartera!E:E,"Comercial",Cartera!F:F,'RESULTADOS MES'!C29,Cartera!J:J,">0",Cartera!C:C,"Aprobado") -> 0 | G28: =+SUMIFS(Cartera!J:J,Cartera!E:E,"Comercial",Cartera!F:F,'RESULTADOS MES'!C29,Cartera!J:J,">0",Cartera!C:C,"Aprobado") -> 0 | H28: =+F28/D28 -> #DIV/0! | I28: =+G28/E28 -> #DIV/0! | J28: =+COUNTIFS(PptoSiguiente!E:E,"Comercial",PptoSiguiente!F:F,'RESULTADOS MES'!C29,PptoSiguiente!I:I,">0",Cartera!C:C,"Aprobado") -> 0 | K28: =SUMIFS(PptoSiguiente!I:I,PptoSiguiente!E:E,"Comercial",PptoSiguiente!F:F,'RESULTADOS MES'!C29,PptoSiguiente!I:I,">0",Cartera!C:C,"Aprobado") -> 0
C29: Prejuridico | D29: =+COUNTIFS(Cartera!E:E,"Comercial",Cartera!F:F,'RESULTADOS MES'!C29,Cartera!K:K,">0",Cartera!C:C,"Aprobado") -> 0 | E29: =+SUBTOTAL(9,E27:E28) -> 0 | F29: =+COUNTIFS(Cartera!E:E,"Comercial",Cartera!F:F,'RESULTADOS MES'!C29,Cartera!L:L,">0",Cartera!C:C,"Aprobado") -> 0 | G29: =+SUBTOTAL(9,G27:G28) -> 0 | H29: =+F29/D29 -> #DIV/0! | I29: =+G29/E29 -> #DIV/0! | J29: =+COUNTIFS(PptoSiguiente!E:E,"Comercial",PptoSiguiente!F:F,'RESULTADOS MES'!C29,PptoSiguiente!K:K,">0",Cartera!C:C,"Aprobado") -> 0 | K29: =+SUBTOTAL(9,K27:K28) -> 0
C30: Del mes | D30: =+COUNTIFS(Cartera!E:E,"Comercial",Cartera!F:F,"Juridico",Cartera!G:G,">0",Cartera!C:C,"Aprobado") -> 0 | E30: =+SUMIFS(Cartera!G:G,Cartera!E:E,"Comercial",Cartera!F:F,"Juridico",Cartera!G:G,">0",Cartera!C:C,"Aprobado") -> 0 | F30: =+COUNTIFS(Cartera!E:E,"Comercial",Cartera!F:F,"Juridico",Cartera!H:H,">0",Cartera!C:C,"Aprobado") -> 0 | G30: =+SUMIFS(Cartera!H:H,Cartera!E:E,"Comercial",Cartera!F:F,"Juridico",Cartera!H:H,">0",Cartera!C:C,"Aprobado") -> 0 | H30: =+F30/D30 -> #DIV/0! | I30: =+G30/E30 -> #DIV/0! | J30: =+COUNTIFS(PptoSiguiente!E:E,"Comercial",PptoSiguiente!F:F,"Juridico",PptoSiguiente!G:G,">0",PptoSiguiente!C:C,"Aprobado") -> 0 | K30: =+SUMIFS(PptoSiguiente!G:G,PptoSiguiente!E:E,"Comercial",PptoSiguiente!F:F,"Juridico",PptoSiguiente!G:G,">0",Cartera!C:C,"Aprobado") -> 0
C31: Vencido | D31: =+COUNTIFS(Cartera!E:E,"Comercial",Cartera!F:F,"Juridico",Cartera!I:I,">0",Cartera!C:C,"Aprobado") -> 0 | E31: =+SUMIFS(Cartera!I:I,Cartera!E:E,"Comercial",Cartera!F:F,"Juridico",Cartera!I:I,">0",Cartera!C:C,"Aprobado") -> 0 | F31: =+COUNTIFS(Cartera!E:E,"Comercial",Cartera!F:F,"Juridico",Cartera!J:J,">0",Cartera!C:C,"Aprobado") -> 0 | G31: =+SUMIFS(Cartera!J:J,Cartera!E:E,"Comercial",Cartera!F:F,"Juridico",Cartera!J:J,">0",Cartera!C:C,"Aprobado") -> 0 | H31: =+F31/D31 -> #DIV/0! | I31: =+G31/E31 -> #DIV/0! | J31: =+COUNTIFS(PptoSiguiente!E:E,"Comercial",PptoSiguiente!F:F,"Juridico",PptoSiguiente!I:I,">0",PptoSiguiente!C:C,"Aprobado") -> 0 | K31: =+SUMIFS(PptoSiguiente!I:I,PptoSiguiente!E:E,"Comercial",PptoSiguiente!F:F,"Juridico",PptoSiguiente!I:I,">0",Cartera!C:C,"Aprobado") -> 0
C32: 90+ (Juridico) | D32: =+COUNTIFS(Cartera!E:E,"Comercial",Cartera!F:F,"Juridico",Cartera!K:K,">0",Cartera!C:C,"Aprobado") -> 0 | E32: =+SUBTOTAL(9,E30:E31) -> 0 | F32: =+COUNTIFS(Cartera!E:E,"Comercial",Cartera!F:F,"Juridico",Cartera!L:L,">0",Cartera!C:C,"Aprobado") -> 0 | G32: =+SUBTOTAL(9,G30:G31) -> 0 | H32: =+F32/D32 -> #DIV/0! | I32: =+G32/E32 -> #DIV/0! | J32: =+COUNTIFS(PptoSiguiente!E:E,"Comercial",PptoSiguiente!F:F,"Juridico",PptoSiguiente!K:K,">0",PptoSiguiente!C:C,"Aprobado") -> 0 | K32: =+SUBTOTAL(9,K30:K31) -> 0
C33: TOTAL PRESUPUESTADO | D33: =+D23+D26+D29+D32 -> 0 | E33: =+SUBTOTAL(9,E21:E32) -> 0 | F33: =+F23+F26+F29+F32 -> 0 | G33: =+SUBTOTAL(9,G21:G32) -> 0 | H33: =+F33/D33 -> #DIV/0! | I33: =+G33/E33 -> #DIV/0! | J33: =+J23+J26+J29 -> 0 | K33: =+SUBTOTAL(9,K21:K29) -> 0
C34: RECAUDO PRESUPUESTADO | D34: =+G33 -> 0 | F34: =+D34/D36 -> #DIV/0!
C35: RECAUDO NO PRESUPUESTADO | D35: =+SUMIFS(Cartera!M:M,Cartera!E:E,"Comercial") -> 0 | F35: =+D35/D36 -> #DIV/0!
C36: TOTAL RECAUDO COMERCIAL | D36: =+D35+G33 -> 0 | F36: =+F34+F35 -> #DIV/0! | G36: TOTAL RECAUDO COMERCIAL ACUMULADO | J36: =+SUMIFS(CarteraHistorico!N:N,CarteraHistorico!E:E,"Comercial") -> 0
B37: CARTERA ADMINISTRATIVA | D37: MES | F37: RECAUDO | H37: CUMPLIMIENTO | J37: SIGUIENTE MES
D38: N° | E38: VALOR | F38: N° | G38: VALOR | H38: N° | I38: VALOR | J38: N° | K38: VALOR
C39: Del mes | D39: =+COUNTIFS(Cartera!E:E,"Administrativa",Cartera!F:F,'RESULTADOS MES'!C41,Cartera!G:G,">0") -> 0 | E39: =SUMIFS(Cartera!G:G,Cartera!E:E,"Administrativa",Cartera!F:F,'RESULTADOS MES'!C41,Cartera!G:G,">0") -> 0 | F39: =+COUNTIFS(Cartera!E:E,"Administrativa",Cartera!F:F,'RESULTADOS MES'!C41,Cartera!H:H,">0") -> 0 | G39: =+SUMIFS(Cartera!H:H,Cartera!E:E,"Administrativa",Cartera!F:F,'RESULTADOS MES'!C41) -> 0 | H39: =+F39/D39 -> #DIV/0! | I39: =+G39/E39 -> #DIV/0! | J39: =COUNTIFS(PptoSiguiente!E:E,"Administrativa",PptoSiguiente!F:F,'RESULTADOS MES'!C41,PptoSiguiente!G:G,">0") -> 0 | K39: =SUMIFS(PptoSiguiente!G:G,PptoSiguiente!E:E,"Administrativa",PptoSiguiente!F:F,'RESULTADOS MES'!C41,PptoSiguiente!G:G,">0") -> 0
C40: Vencido | D40: =+COUNTIFS(Cartera!E:E,"Administrativa",Cartera!F:F,'RESULTADOS MES'!C41,Cartera!I:I,">0") -> 0 | E40: =SUMIFS(Cartera!I:I,Cartera!E:E,"Administrativa",Cartera!F:F,'RESULTADOS MES'!C41,Cartera!I:I,">0") -> 0 | F40: =+COUNTIFS(Cartera!E:E,"Administrativa",Cartera!F:F,'RESULTADOS MES'!C41,Cartera!J:J,">0") -> 0 | G40: =+SUMIFS(Cartera!J:J,Cartera!E:E,"Administrativa",Cartera!F:F,'RESULTADOS MES'!C41) -> 0 | H40: =+F40/D40 -> #DIV/0! | I40: =+G40/E40 -> #DIV/0! | J40: =+COUNTIFS(PptoSiguiente!E:E,"Administrativa",PptoSiguiente!F:F,'RESULTADOS MES'!C41,PptoSiguiente!I:I,">0") -> 0 | K40: =SUMIFS(PptoSiguiente!I:I,PptoSiguiente!E:E,"Administrativa",PptoSiguiente!F:F,'RESULTADOS MES'!C41,PptoSiguiente!I:I,">0") -> 0
C41: -30-30 | D41: =+COUNTIFS(Cartera!E:E,"Administrativa",Cartera!F:F,'RESULTADOS MES'!C41,Cartera!K:K,">0") -> 0 | E41: =+SUBTOTAL(9,E39:E40) -> 0 | F41: =+COUNTIFS(Cartera!E:E,"Administrativa",Cartera!F:F,'RESULTADOS MES'!C41,Cartera!L:L,">0") -> 0 | G41: =+SUBTOTAL(9,G39:G40) -> 0 | H41: =+F41/D41 -> #DIV/0! | I41: =+G41/E41 -> #DIV/0! | J41: =+COUNTIFS(PptoSiguiente!E:E,"Administrativa",PptoSiguiente!F:F,'RESULTADOS MES'!C41,PptoSiguiente!K:K,">0") -> 0 | K41: =+SUBTOTAL(9,K39:K40) -> 0
...

Sheet Ventas
A1: Item | B1: Cantidad Mes | C1: Valor Mes | D1: Cantidad Acum | E1: Valor Acumulado

Sheet Recaudos
A1: Fecha | B1: Adj | C1: Cliente | D1: Inmueble | E1: Valor | F1: Operación | G1: FormaPago

Sheet Detalle Ventas
A1: Fecha | B1: Adj | C1: Nombre | D1: Inmueble | E1: Valor | F1: Base Comision | G1: % Comis Operativa | H1: $ Comis Operativa | I1: $Comis Corporativa | J1: Plata Mesa | K1: Plata Mes

Sheet Cartera
A1: Adjudicacion | B1: Cliente | C1: Estado | D1: Origen | E1: TipoCartera | F1: Edad | G1: pptomes | H1: rcdomes | I1: pptovencido | J1: rcdovencido | K1: pptototal | L1: rcdopptado | M1: rcdonopptado | N1: rcdototal

Sheet CarteraHistorico
A1: Adjudicacion | B1: Cliente | C1: Estado | D1: Origen | E1: TipoCartera | F1: Edad | G1: pptomes | H1: rcdomes | I1: pptovencido | J1: rcdovencido | K1: pptototal | L1: rcdopptado | M1: rcdonopptado | N1: rcdototal | O1: periodo

Sheet PptoSiguiente
A1: Adjudicacion | B1: Cliente | C1: Estado | D1: Origen | E1: TipoCartera | F1: Edad | G1: pptomes | H1: rcdomes | I1: pptovencido | J1: rcdovencido | K1: pptototal | L1: rcdopptado | M1: rcdonopptado | N1: rcdototal

Sheet Gastos Mes
A1: Fecha | B1: Comprobante | C1: Cuenta | D1: Descripcion Cuenta | E1: Tercero | F1: Descripcion Gasto | G1: Item | H1: Valor | I1: Empresa

Sheet Metas
A1: Oficina | B1: Mes | C1: Año | D1: 12 | E1: 13 | F1: 14 | G1: 21 | H1: 22 | I1: 24
D2: Rec.Cuotas Mes Comercial | E2: Rec. Ctas Vencidas Comercial | F2: Rec. Prejudridico Comercial | G2: Rec.Cuotas Mes Admin | H2: Rec. Ctas Vencidas Admin | I2: Rec. Prejudridico Admin
A3: Sandville Beach | B3: 10 | C3: 2018 | D3: 1 | E3: 0.5 | F3: 0.15 | G3: 0.5 | H3: 0.7 | I3: 0.05
A4: Sandville del Sol | B4: 10 | C4: 2018 | D4: 0.5 | E4: 0.7 | F4: 0.1 | G4: 0.5 | H4: 0.8 | I4: 0.1
A5: Sandville del Mar | B5: 10 | C5: 2018 | D5: 0.8 | E5: 0.5 | F5: 0.2 | G5: 0.6 | H5: 0.8 | I5: 0.15
A6: Westville | B6: 10 | C6: 2018 | D6: 0.8 | E6: 0.7 | F6: 0.2 | G6: 0.6 | H6: 0.85 | I6: 0.15

Sheet Hoja2
B1: MONTERIA | C1: SINCELEJO | D1: MEDELLIN | E1: SANDVILLE | F1: WESTVILLE
A2: GASTOS DE NOMINA
A3: 14200101 SUELDOS Y SALARIOS | B3: 8914088 | C3: 741011 | D3: 16946296 | E3: 26601395 | F3: 3320392
A4: 14200107 SUBSIDIO DE TRANSPORTE | B4: 661590 | C4: 82331 | D4: 699815 | E4: 1443736 | F4: 264636
A5: 14200108 AUXILIO DE TRANSPORTE | B5: 0 | C5: 0 | D5: 0 | E5: 0 | F5: 0
A6: 14200109 AUXILIO DE RODAMIENTO | B6: 0 | C6: 0 | D6: 0 | E6: 0 | F6: 0
A7: 14200113 BONIFICACIÓN SALARIAL | B7: 0 | C7: 0 | D7: 0 | E7: 0 | F7: 0
A8: 14200115 BONIFICACION SPIFF | B8: 0 | C8: 0 | D8: 0 | E8: 0 | F8: 0
A9: 14200116 BONIFICACIÓN NO SALARIAL | B9: 300000 | C9: 0 | D9: 300000 | E9: 600000 | F9: 450000
A10: 14200143 VACACIONES | B10: 418514 | C10: 120291 | D10: 1799623 | E10: 2338428 | F10: 130765
A11: 14200147 PRIMA DE SERVICIO | B11: 797976 | C11: 68611 | D11: 1944942 | E11: 2811529 | F11: 298753
A12: 14200148 CESANTIAS | B12: 801652 | C12: 107572 | D12: 1444942 | E12: 2354166 | F12: 298753
A13: 14200149 INTERESES DE CESANTIAS | B13: 90770 | C13: 0 | D13: 173400 | E13: 264170 | F13: 35853
A14: 14200156 APORTES SOBRE LA NÓMINA AL ICBF | B14: 254300 | C14: 0 | D14: 500200 | E14: 754500 | F14: 99800
... A21: TOTAL | B21: 14574690 | C21: 1119816 | D21: 28198718 | E21: 43893224 | F21: 5796152
A23: GASTOS OPERACIONALES
A24: 14400106 ARRENDAMIENTOS OFICINAS | B24: 2148748 | C24: 0 | D24: 14467814 | E24: 16616562 | F24: 0
A25: 14400108 SEGUROS (OFICINAS ACTIVOS ETC) | B25: 0 | C25: 0 | D25: 0 | E25: 0 | F25: 0
A26: 14400109 SERVICIOS SEGURIDAD Y VIGILANCIA | B26: 153564 | C26: 82557 | D26: 235100 | E26: 471221 | F26: 0
A27: 14400110 SERVICIO DE ACUEDUCTO ASEO Y ALCANTARILLADO | B27: 103630 | C27: 136830 | D27: 526587 | E27: 767047 | F27: 0
A28: 14400111 SERVICIO ENERGIA ELECTRICA | B28: 1743200 | C28: 398910 | D28: 1293273 | E28: 3435383 | F28: 0
A29: 14400112 SERVICIO DE TELEFONIA CELULARES | B29: 172207 | C29: 0 | D29: 2016807 | E29: 2189014 | F29: 0
A30: 14400113 SERVICIO DE INTERNET TELEFONO Y TELEVISION | B30: 1124760 | C30: 693397 | D30: 3487215 | E30: 5305372 | F30: 0
A31: 14400114 SERVICIO DE TRANSPORTE | B31: 200000 | C31: 0 | D31: 0 | E31: 200000 | F31: 0
A32: 14400115 SERVICIO DE GAS | B32: 3330 | C32: 19686 | D32: 13056 | E32: 36072 | F32: 0
A33: 14400116 GASTOS LEGALES MATRICULA MERCANTIL | B33: 5500 | C33: 0 | D33: 0 | E33: 5500 | F33: 0
A34: 14400117 GASTOS LEGALES GASTOS NOTARIALES | B34: 1726204 | C34: 0 | D34: 200559 | E34: 1926763 | F34: 0
A35: 14400118 GASTOS LEGALES TRAMITES Y PERMISOS | B35: 0 | C35: 0 | D35: 15400 | E35: 15400 | F35: 1000000
... A75: TOTAL | B75: 21370494 | C75: 5662444.4 | D75: 34117946 | E75: 61150884 | F75: 1552934.3
A77: TOTAL GASTO ADMINISTRATIVO | B77: 35945184
A79: GASTOS DE NOMINA
A80: 52050600 SUELDOS | B80: 15846542
A81: 52051500 HORAS EXTRAS Y RECARGOS | B81: 182290
A82: 52052700 AUXILIO DE TRANSPORTE | B82: 1305533
A83: 52053000 CESANTIAS | B83: 2130634.2
A84: 52053300 INTERESES SOBRE CESANTIAS | B84: 211672.88
A85: 52053600 PRIMA DE SERVICIOS | B85: 1826510.9
A86: 52053900 VACACIONES | B86: 3139762
A87: 52054501 AUXILIO DE VIVIENDA | B87: 1000000
A88: 52054502 AUXILIO DE ALIMENTACION | B88: 250000
...

Sheet SANDVILLE
A1: INFORME GENERAL DE GASTOS SANDVILLE SEPTIEMBRE 2018
A4: VENTAS | C4: RUBRO | D4: N° | E4: VALOR
C5: VENTAS DEL MES | D5: 5 | E5: 391200000
C6: a. VENTAS PROCESABLES | D6: 5 | E6: 391200000
C7: b. VENTAS NO PROCESABLES | D7: 0 | E7: 0
C8: VENTAS RADICADAS | D8: 5 | E8: 391200000
C9: VENTAS NO REGISTRABLES | D9: 0 | E9: 0
C10: RECAUDO POR VENTAS | D10: VALOR
C11: PLATA EN MESA | D11: 33893750
C12: PLATA EN MES | D12: 21000000
C13: TOTAL RECAUDO VENTAS DEL MES | D13: =+D11+D12 -> 54893750
C14: TOTAL RECAUDO CARTERA | D14: 328919119
C15: TOTAL INGRESO DEL MES | D15: =+D13+D14 -> 383812869
A16: CUENTA | D16: Mes Anterior | E16: Mes Actual | F16: Variacion | G16: %Ventas Brutas | H16: % Ventas Procesables | I16: %Recaudo Ventas Mes | J16: %Recaudo Cartera | K16: %Recaudo Total Mes
A17: COMERCIAL | B17: NOMINA COMERCIAL | C17: 52050600 SUELDOS | D17: 0 | E17: 6712850 | F17: =IFERROR(+(E17-D17)/D17,"N/A") -> N/A | G17: =+E17/$E$5 -> 0.017159637 | H17: =+E17/$E$6 -> 0.017159637 | I17: =+E17/$D$13 -> 0.12228806 | J17: =+E17/$D$14 -> 0.020408817 | K17: =+E17/$D$15 -> 0.017489903
C18: 52051500 HORAS EXTRAS Y RECARGOS | D18: 0 | E18: 113931 | F18: =IFERROR(+(E18-D18)/D18,"N/A") -> N/A | G18: =+E18/$E$5 -> 0.00029123466 | H18: =+E18/$E$6 -> 0.00029123466 | I18: =+E18/$D$13 -> 0.0020754822 | J18: =+E18/$D$14 -> 0.00034637999 | K18: =+E18/$D$15 -> 0.00029683997
C19: 52052700 AUXILIO DE TRANSPORTE | D19: 0 | E19: 598369.5 | F19: =IFERROR(+(E19-D19)/D19,"N/A") -> N/A | G19: =+E19/$E$5 -> 0.0015295744 | H19: =+E19/$E$6 -> 0.0015295744 | I19: =+E19/$D$13 -> 0.010900503 | J19: =+E19/$D$14 -> 0.0018191995 | K19: =+E19/$D$15 -> 0.0015590136
C20: 52053000 CESANTIAS | D20: 0 | E20: 1452011.5 | F20: =IFERROR(+(E20-D20)/D20,"N/A") -> N/A | G20: =+E20/$E$5 -> 0.0037116858 | H20: =+E20/$E$6 -> 0.0037116858 | I20: =+E20/$D$13 -> 0.026451308 | J20: =+E20/$D$14 -> 0.0044144941 | K20: =+E20/$D$15 -> 0.0037831235
C21: 52053300 INTERESES SOBRE CESANTIAS | D21: 0 | E21: 69255 | F21: =IFERROR(+(E21-D21)/D21,"N/A") -> N/A | G21: =+E21/$E$5 -> 0.00017703221 | H21: =+E21/$E$6 -> 0.00017703221 | I21: =+E21/$D$13 -> 0.001261619 | J21: =+E21/$D$14 -> 0.00021055328 | K21: =+E21/$D$15 -> 0.00018043949
C22: 52053600 PRIMA DE SERVICIOS | D22: 0 | E22: 895921.5 | F22: =IFERROR(+(E22-D22)/D22,"N/A") -> N/A | G22: =+E22/$E$5 -> 0.0022901879 | H22: =+E22/$E$6 -> 0.0022901879 | I22: =+E22/$D$13 -> 0.016321011 | J22: =+E22/$D$14 -> 0.0027238353 | K22: =+E22/$D$15 -> 0.0023342664
C23: 52053900 VACACIONES | D23: 0 | E23: 1039323 | F23: =IFERROR(+(E23-D23)/D23,"N/A") -> N/A | G23: =+E23/$E$5 -> 0.0026567561 | H23: =+E23/$E$6 -> 0.0026567561 | I23: =+E23/$D$13 -> 0.018933358 | J23: =+E23/$D$14 -> 0.0031598133 | K23: =+E23/$D$15 -> 0.0027078899
C24: 52054501 AUXILIO DE VIVIENDA | D24: 0 | E24: 250000 | F24: =IFERROR(+(E24-D24)/D24,"N/A") -> N/A | G24: =+E24/$E$5 -> 0.0006390593 | H24: =+E24/$E$6 -> 0.0006390593 | I24: =+E24/$D$13 -> 0.0045542525 | J24: =+E24/$D$14 -> 0.00076006527 | K24: =+E24/$D$15 -> 0.00065135909
C25: 52054502 AUXILIO DE ALIMENTACION | D25: 0 | E25: 250000 | F25: =IFERROR(+(E25-D25)/D25,"N/A") -> N/A | G25: =+E25/$E$5 -> 0.0006390593 | H25: =+E25/$E$6 -> 0.0006390593 | I25: =+E25/$D$13 -> 0.0045542525 | J25: =+E25/$D$14 -> 0.00076006527 | K25: =+E25/$D$15 -> 0.00065135909
C26: 52056800 APORTES A ADMINISTRADORAS DE RIESGOS PRO | D26: 0 | E26: 121150 | F26: =IFERROR(+(E26-D26)/D26,"N/A") -> N/A | G26: =+E26/$E$5 -> 0.00030968814 | H26: =+E26/$E$6 -> 0.00030968814 | I26: =+E26/$D$13 -> 0.0022069908 | J26: =+E26/$D$14 -> 0.00036832763 | K26: =+E26/$D$15 -> 0.00031564861
C27: 52056900 APORTES A ENTIDADES PROMOTORAS DE SALUD | D27: 0 | E27: 1262250 | F27: =IFERROR(+(E27-D27)/D27,"N/A") -> N/A | G27: =+E27/$E$5 -> 0.0032266104 | H27: =+E27/$E$6 -> 0.0032266104 | I27: =+E27/$D$13 -> 0.022994421 | J27: =+E27/$D$14 -> 0.0038375696 | K27: =+E27/$D$15 -> 0.003288712
C28: 52057000 APORTES A FONDOS DE PENSION Y/O CESANTIA | D28: 0 | E28: 2786050 | F28: =IFERROR(+(E28-D28)/D28,"N/A") -> N/A | G28: =+E28/$E$5 -> 0.0071218047 | H28: =+E28/$E$6 -> 0.0071218047 | I28: =+E28/$D$13 -> 0.050753501 | J28: =+E28/$D$14 -> 0.0084703194 | K28: =+E28/$D$15 -> 0.0072588759
C29: 52057200 APORTES CAJAS DE COMPENSACION FAMILIAR | D29: 0 | E29: 725550 | F29: =IFERROR(+(E29-D29)/D29,"N/A") -> N/A | G29: =+E29/$E$5 -> 0.0018546779 | H29: =+E29/$E$6 -> 0.0018546779 | I29: =+E29/$D$13 -> 0.013217352 | J29: =+E29/$D$14 -> 0.0022058614 | K29: =+E29/$D$15 -> 0.0018903743
... C35: TOTAL NOMINA COMERCIAL | D35: 0 | E35: 16784326 | F35: =IFERROR(+(E35-D35)/D35,"N/A") -> N/A | G35: =+E35/$E$5 -> 0.04290472 | H35: =+E35/$E$6 -> 0.04290472 | I35: =+E35/$D$13 -> 0.30576025 | J35: =+E35/$D$14 -> 0.051028735 | K35: =+E35/$D$15 -> 0.043730494
B36: OPERACIÓN COMERCIAL | C36: 14400202 G.T.T. ASESORES | D36: 862500 | E36: 5275000 | F36: =IFERROR(+(E36-D36)/D36,"N/A") -> 5.115942 | G36: =+E36/$E$5 -> 0.013484151 | H36: =+E36/$E$6 -> 0.013484151 | I36: =+E36/$D$13 -> 0.096094728 | J36: =+E36/$D$14 -> 0.016037377 | K36: =+E36/$D$15 -> 0.013743677
C37: 14400203 G.T.T. PROMOTORES | D37: 0 | E37: 75000 | F37: =IFERROR(+(E37-D37)/D37,"N/A") -> N/A | G37: =+E37/$E$5 -> 0.00019171779 | H37: =+E37/$E$6 -> 0.00019171779 | I37: =+E37/$D$13 -> 0.0013662758 | J37: =+E37/$D$14 -> 0.00022801958 | K37: =+E37/$D$15 -> 0.00019540773
C38: 14400204 EVENTOS COMERCIALES | D38: 4149500 | E38: 175050 | F38: =IFERROR(+(E38-D38)/D38,"N/A") -> -0.95781419 | G38: =+E38/$E$5 -> 0.00044746933 | H38: =+E38/$E$6 -> 0.00044746933 | I38: =+E38/$D$13 -> 0.0031888876 | J38: =+E38/$D$14 -> 0.0005321977 | K38: =+E38/$D$15 -> 0.00045608163
C39: 14400205 ALIMENTOS | D39: 199500 | E39: 371796 | F39: =IFERROR(+(E39-D39)/D39,"N/A") -> 0.8636391 | G39: =+E39/$E$5 -> 0.00095039877 | H39: =+E39/$E$6 -> 0.00095039877 | I39: =+E39/$D$13 -> 0.0067730115 | J39: =+E39/$D$14 -> 0.0011303569 | K39: =+E39/$D$15 -> 0.00096869081
C40: 14400210 ALIMENTACION PERSONAL EN EVENTO | D40: 397700 | E40: 447698 | F40: =IFERROR(+(E40-D40)/D40,"N/A") -> 0.12571788 | G40: =+E40/$E$5 -> 0.0011444223 | H40: =+E40/$E$6 -> 0.0011444223 | I40: =+E40/$D$13 -> 0.008155719 | J40: =+E40/$D$14 -> 0.0013611188 | K40: =+E40/$D$15 -> 0.0011664486
C41: 14400212 OTROS GASTOS COMERCIALES | D41: 0 | E41: 25650 | F41: =IFERROR(+(E41-D41)/D41,"N/A") -> N/A | G41: =+E41/$E$5 -> 6.5567485e-05 | H41: =+E41/$E$6 -> 6.5567485e-05 | I41: =+E41/$D$13 -> 0.00046726631 | J41: =+E41/$D$14 -> 7.7982697e-05 | K41: =+E41/$D$15 -> 6.6829442e-05
C42: 14400213 TRANSPORTES A EVENTOS | D42: 32700 | E42: 140000 | F42: =IFERROR(+(E42-D42)/D42,"N/A") -> 3.2813456 | G42: =+E42/$E$5 -> 0.00035787321 | H42: =+E42/$E$6 -> 0.00035787321 | I42: =+E42/$D$13 -> 0.0025503814 | J42: =+E42/$D$14 -> 0.00042563655 | K42: =+E42/$D$15 -> 0.00036476109
C43: 14400214 BONIFICACION SPIFF | D43: 0 | E43: 250000 | F43: =IFERROR(+(E43-D43)/D43,"N/A") -> N/A | G43: =+E43/$E$5 -> 0.0006390593 | H43: =+E43/$E$6 -> 0.0006390593 | I43: =+E43/$D$13 -> 0.0045542525 | J43: =+E43/$D$14 -> 0.00076006527 | K43: =+E43/$D$15 -> 0.00065135909
C44: 14400215 PLATA EN MESA | D44: 0 | E44: 100000 | F44: =IFERROR(+(E44-D44)/D44,"N/A") -> N/A | G44: =+E44/$E$5 -> 0.00025562372 | H44: =+E44/$E$6 -> 0.00025562372 | I44: =+E44/$D$13 -> 0.001821701 | J44: =+E44/$D$14 -> 0.00030402611 | K44: =+E44/$D$15 -> 0.00026054363
C45: 14400217 QS POR JEFE DE PROMOCIÓN | D45: 241000 | E45: 104500 | F45: =IFERROR(+(E45-D45)/D45,"N/A") -> -0.56639004 | G45: =+E45/$E$5 -> 0.00026712679 | H45: =+E45/$E$6 -> 0.00026712679 | I45: =+E45/$D$13 -> 0.0019036776 | J45: =+E45/$D$14 -> 0.00031770728 | K45: =+E45/$D$15 -> 0.0002722681
C46: 14400219 HOSSTES | D46: 285000 | E46: 280000 | F46: =IFERROR(+(E46-D46)/D46,"N/A") -> -0.01754386 | G46: =+E46/$E$5 -> 0.00071574642 | H46: =+E46/$E$6 -> 0.00071574642 | I46: =+E46/$D$13 -> 0.0051007628 | J46: =+E46/$D$14 -> 0.00085127311 | K46: =+E46/$D$15 -> 0.00072952218
C47: 14400221 GASTOS POR ÚTILES Y PAPELERÍA | D47: 155681 | E47: 67815 | F47: =IFERROR(+(E47-D47)/D47,"N/A") -> -0.56439771 | G47: =+E47/$E$5 -> 0.00017335123 | H47: =+E47/$E$6 -> 0.00017335123 | I47: =+E47/$D$13 -> 0.0012353865 | J47: =+E47/$D$14 -> 0.00020617531 | K47: =+E47/$D$15 -> 0.00017668767
...

Sheet WESTVILLE
A1: INFORME GENERAL DE GASTOS WESTVILLE SEPTIEMBRE 2018
A4: VENTAS | C4: RUBRO | D4: N° | E4: VALOR
C5: VENTAS DEL MES | D5: 6 | E5: 407000000
C6: a. VENTAS PROCESABLES | D6: 6 | E6: 407000000
C7: b. VENTAS NO PROCESABLES | D7: 0 | E7: 0
C8: VENTAS RADICADAS | D8: 5 | E8: 341000000
C9: VENTAS NO REGISTRABLES | D9: 0 | E9: 0
C10: RECAUDO POR VENTAS | D10: VALOR
C11: PLATA EN MESA | D11: 10875000
C12: PLATA EN MES | D12: 40000000
C13: TOTAL RECAUDO VENTAS DEL MES | D13: =+D11+D12 -> 50875000
C14: TOTAL RECAUDO CARTERA | D14: 134954502
C15: TOTAL INGRESO DEL MES | D15: =+D13+D14 -> 185829502
A16: CUENTA | D16: Mes Anterior | E16: Mes Actual | F16: Variacion | G16: %Ventas Brutas | H16: % Ventas Procesables | I16: %Recaudo Ventas Mes | J16: %Recaudo Total Mes | K16: %Recaudo Total Mes
A17: COMERCIAL | B17: NOMINA COMERCIAL | C17: 52050600 SUELDOS | D17: 15846542 | E17: 6712850 | F17: =IFERROR(+(E17-D17)/D17,"N/A") -> -0.57638392 | G17: =+E17/$E$5 -> 0.016493489 | H17: =+E17/$E$6 -> 0.016493489 | I17: =+E17/$D$13 -> 0.13194791 | J17: =+E17/$D$14 -> 0.049741579 | K17: =+E17/$D$15 -> 0.036123704
C18: 52051500 HORAS EXTRAS Y RECARGOS | D18: 182290 | E18: 113931 | F18: =IFERROR(+(E18-D18)/D18,"N/A") -> -0.37500137 | G18: =+E18/$E$5 -> 0.00027992875 | H18: =+E18/$E$6 -> 0.00027992875 | I18: =+E18/$D$13 -> 0.00223943 | J18: =+E18/$D$14 -> 0.00084421785 | K18: =+E18/$D$15 -> 0.00061309425
C19: 52052700 AUXILIO DE TRANSPORTE | D19: 1305533 | E19: 598369.5 | F19: =IFERROR(+(E19-D19)/D19,"N/A") -> -0.54166651 | G19: =+E19/$E$5 -> 0.0014701953 | H19: =+E19/$E$6 -> 0.0014701953 | I19: =+E19/$D$13 -> 0.011761563 | J19: =+E19/$D$14 -> 0.004433861 | K19: =+E19/$D$15 -> 0.0032199919
C20: 52053000 CESANTIAS | D20: 2130634.2 | E20: 1452011.5 | F20: =IFERROR(+(E20-D20)/D20,"N/A") -> -0.31850738 | G20: =+E20/$E$5 -> 0.0035675958 | H20: =+E20/$E$6 -> 0.0035675958 | I20: =+E20/$D$13 -> 0.028540767 | J20: =+E20/$D$14 -> 0.010759267 | K20: =+E20/$D$15 -> 0.0078136759
C21: 52053300 INTERESES SOBRE CESANTIAS | D21: 211672.88 | E21: 69255 | F21: =IFERROR(+(E21-D21)/D21,"N/A") -> -0.67282063 | G21: =+E21/$E$5 -> 0.00017015971 | H21: =+E21/$E$6 -> 0.00017015971 | I21: =+E21/$D$13 -> 0.0013612776 | J21: =+E21/$D$14 -> 0.00051317295 | K21: =+E21/$D$15 -> 0.00037268033
C22: 52053600 PRIMA DE SERVICIOS | D22: 1826510.9 | E22: 895921.5 | F22: =IFERROR(+(E22-D22)/D22,"N/A") -> -0.5094902 | G22: =+E22/$E$5 -> 0.0022012813 | H22: =+E22/$E$6 -> 0.0022012813 | I22: =+E22/$D$13 -> 0.017610251 | J22: =+E22/$D$14 -> 0.0066386929 | K22: =+E22/$D$15 -> 0.0048212016
C23: 52053900 VACACIONES | D23: 3139762 | E23: 1039323 | F23: =IFERROR(+(E23-D23)/D23,"N/A") -> -0.66898032 | G23: =+E23/$E$5 -> 0.0025536192 | H23: =+E23/$E$6 -> 0.0025536192 | I23: =+E23/$D$13 -> 0.020428953 | J23: =+E23/$D$14 -> 0.0077012844 | K23: =+E23/$D$15 -> 0.0055928848
C24: 52054501 AUXILIO DE VIVIENDA | D24: 1000000 | E24: 250000 | F24: =IFERROR(+(E24-D24)/D24,"N/A") -> -0.75 | G24: =+E24/$E$5 -> 0.00061425061 | H24: =+E24/$E$6 -> 0.00061425061 | I24: =+E24/$D$13 -> 0.0049140049 | J24: =+E24/$D$14 -> 0.0018524762 | K24: =+E24/$D$15 -> 0.0013453192
C25: 52054502 AUXILIO DE ALIMENTACION | D25: 250000 | E25: 250000 | F25: =IFERROR(+(E25-D25)/D25,"N/A") -> 0 | G25: =+E25/$E$5 -> 0.00061425061 | H25: =+E25/$E$6 -> 0.00061425061 | I25: =+E25/$D$13 -> 0.0049140049 | J25: =+E25/$D$14 -> 0.0018524762 | K25: =+E25/$D$15 -> 0.0013453192
C26: 52056800 APORTES A ADMINISTRADORAS DE RIESGOS PRO | D26: 225200 | E26: 121150 | F26: =IFERROR(+(E26-D26)/D26,"N/A") -> -0.46203375 | G26: =+E26/$E$5 -> 0.00029766585 | H26: =+E26/$E$6 -> 0.00029766585 | I26: =+E26/$D$13 -> 0.0023813268 | J26: =+E26/$D$14 -> 0.00089770996 | K26: =+E26/$D$15 -> 0.00065194169
C27: 52056900 APORTES A ENTIDADES PROMOTORAS DE SALUD | D27: 2230900 | E27: 1262250 | F27: =IFERROR(+(E27-D27)/D27,"N/A") -> -0.43419696 | G27: =+E27/$E$5 -> 0.0031013514 | H27: =+E27/$E$6 -> 0.0031013514 | I27: =+E27/$D$13 -> 0.024810811 | J27: =+E27/$D$14 -> 0.0093531522 | K27: =+E27/$D$15 -> 0.0067925167
C28: 52057000 APORTES A FONDOS DE PENSION Y/O CESANTIA | E28: 2786050 | F28: =IFERROR(+(E28-D28)/D28,"N/A") -> N/A | G28: =+E28/$E$5 -> 0.0068453317 | H28: =+E28/$E$6 -> 0.0068453317 | I28: =+E28/$D$13 -> 0.054762654 | J28: =+E28/$D$14 -> 0.020644365 | K28: =+E28/$D$15 -> 0.014992506
C29: 52057200 APORTES CAJAS DE COMPENSACION FAMILIAR | D29: 1343000 | E29: 725550 | F29: =IFERROR(+(E29-D29)/D29,"N/A") -> -0.45975428 | G29: =+E29/$E$5 -> 0.0017826781 | H29: =+E29/$E$6 -> 0.0017826781 | I29: =+E29/$D$13 -> 0.014261425 | J29: =+E29/$D$14 -> 0.0053762564 | K29: =+E29/$D$15 -> 0.0039043854
C30: 52057500 APORTES I C B F | D30: 532000 | E30: 260350 | F30: =IFERROR(+(E30-D30)/D30,"N/A") -> -0.5106203 | G30: =+E30/$E$5 -> 0.00063968059 | H30: =+E30/$E$6 -> 0.00063968059 | I30: =+E30/$D$13 -> 0.0051174447 | J30: =+E30/$D$14 -> 0.0019291687 | K30: =+E30/$D$15 -> 0.0014010154
C31: 52057800 SENA | D31: 354900 | E31: 173750 | F31: =IFERROR(+(E31-D31)/D31,"N/A") -> -0.51042547 | G31: =+E31/$E$5 -> 0.00042690418 | H31: =+E31/$E$6 -> 0.00042690418 | I31: =+E31/$D$13 -> 0.0034152334 | J31: =+E31/$D$14 -> 0.0012874709 | K31: =+E31/$D$15 -> 0.00093499686
C32: 52056000 INDEMNIZACIONES LABORALES | D32: 976560 | E32: 0 | F32: =IFERROR(+(E32-D32)/D32,"N/A") -> -1 | G32: =+E32/$E$5 -> 0 | H32: =+E32/$E$6 -> 0 | I32: =+E32/$D$13 -> 0 | J32: =+E32/$D$14 -> 0 | K32: =+E32/$D$15 -> 0
C33: 52058400 GASTOS MEDICOS Y DROGAS | D33: 55800 | E33: 55800 | F33: =IFERROR(+(E33-D33)/D33,"N/A") -> 0 | G33: =+E33/$E$5 -> 0.00013710074 | H33: =+E33/$E$6 -> 0.00013710074 | I33: =+E33/$D$13 -> 0.0010968059 | J33: =+E33/$D$14 -> 0.00041347268 | K33: =+E33/$D$15 -> 0.00030027525
C34: 52157000 IVA DESCONTABLE | D34: 25840 | E34: 17765 | F34: =IFERROR(+(E34-D34)/D34,"N/A") -> -0.3125 | G34: =+E34/$E$5 -> 4.3648649e-05 | H34: =+E34/$E$6 -> 4.3648649e-05 | I34: =+E34/$D$13 -> 0.00034918919 | J34: =+E34/$D$14 -> 0.00013163696 | K34: =+E34/$D$15 -> 9.5598384e-05
C35: TOTAL NOMINA COMERCIAL | D35: 36660345 | E35: 16784326 | F35: =IFERROR(+(E35-D35)/D35,"N/A") -> -0.54216671 | G35: =+E35/$E$5 -> 0.041239131 | H35: =+E35/$E$6 -> 0.041239131 | I35: =+E35/$D$13 -> 0.32991305 | J35: =+E35/$D$14 -> 0.12437026 | K35: =+E35/$D$15 -> 0.090321108
B36: OPERACIÓN COMERCIAL | C36: 14400202 G.T.T. ASESORES | D36: =+VLOOKUP(C36,Hoja2!$A$105:$F$143,6,FALSE) -> 7230000 | E36: 6885000 | F36: =IFERROR(+(E36-D36)/D36,"N/A") -> -0.047717842 | G36: =+E36/$E$5 -> 0.016916462 | H36: =+E36/$E$6 -> 0.016916462 | I36: =+E36/$D$13 -> 0.1353317 | J36: =+E36/$D$14 -> 0.051017194 | K36: =+E36/$D$15 -> 0.037050091
C37: 14400204 EVENTOS COMERCIALES | D37: =+VLOOKUP(C37,Hoja2!$A$105:$F$143,6,FALSE) -> 9782460 | E37: =13381632+5383590 -> 18765222 | F37: =IFERROR(+(E37-D37)/D37,"N/A") -> 0.91825185 | G37: =+E37/$E$5 -> 0.046106197 | H37: =+E37/$E$6 -> 0.046106197 | I37: =+E37/$D$13 -> 0.36884957 | J37: =+E37/$D$14 -> 0.13904851 | K37: =+E37/$D$15 -> 0.10098086
C38: 14400205 ALIMENTOS | D38: =+VLOOKUP(C38,Hoja2!$A$105:$F$143,6,FALSE) -> 0 | E38: 223900 | F38: =IFERROR(+(E38-D38)/D38,"N/A") -> N/A | G38: =+E38/$E$5 -> 0.00055012285 | H38: =+E38/$E$6 -> 0.00055012285 | I38: =+E38/$D$13 -> 0.0044009828 | J38: =+E38/$D$14 -> 0.0016590777 | K38: =+E38/$D$15 -> 0.0012048679
C39: 14400209 CAPACITACION ASESORES COMERCIALES | D39: =+VLOOKUP(C39,Hoja2!$A$105:$F$143,6,FALSE) -> 0 | E39: 1414000 | F39: =IFERROR(+(E39-D39)/D39,"N/A") -> N/A | G39: =+E39/$E$5 -> 0.0034742015 | H39: =+E39/$E$6 -> 0.0034742015 | I39: =+E39/$D$13 -> 0.027793612 | J39: =+E39/$D$14 -> 0.010477605 | K39: =+E39/$D$15 -> 0.0076091255
C40: 14400210 ALIMENTACION PERSONAL EN EVENTO | D40: =+VLOOKUP(C40,Hoja2!$A$105:$F$143,6,FALSE) -> 938796 | E40: 444370 | F40: =IFERROR(+(E40-D40)/D40,"N/A") -> -0.52665968 | G40: =+E40/$E$5 -> 0.0010918182 | H40: =+E40/$E$6 -> 0.0010918182 | I40: =+E40/$D$13 -> 0.0087345455 | J40: =+E40/$D$14 -> 0.0032927394 | K40: =+E40/$D$15 -> 0.002391278
C41: 14400213 TRANSPORTES A EVENTOS | D41: =+VLOOKUP(C41,Hoja2!$A$105:$F$143,6,FALSE) -> 394000 | E41: 37000 | F41: =IFERROR(+(E41-D41)/D41,"N/A") -> -0.90609137 | G41: =+E41/$E$5 -> 9.0909091e-05 | H41: =+E41/$E$6 -> 9.0909091e-05 | I41: =+E41/$D$13 -> 0.00072727273 | J41: =+E41/$D$14 -> 0.00027416647 | K41: =+E41/$D$15 -> 0.00019910724
C42: 14400214 BONIFICACION SPIFF | D42: =+VLOOKUP(C42,Hoja2!$A$105:$F$143,6,FALSE) -> 100000 | E42: 400000 | F42: =IFERROR(+(E42-D42)/D42,"N/A") -> 3 | G42: =+E42/$E$5 -> 0.00098280098 | H42: =+E42/$E$6 -> 0.00098280098 | I42: =+E42/$D$13 -> 0.0078624079 | J42: =+E42/$D$14 -> 0.0029639619 | K42: =+E42/$D$15 -> 0.0021525107
...

Sheet Hoja3
A1: Expr1 | B1: Expr2 | C1: SumaDeSumaDeVALOR
A2: G1 | B2: NOMINA COMERCIAL | C2: 33568653
A3: Expr1 | B3: Expr2 | C3: SumaDeSumaDeVALOR | D3: EMPRESA
A4: G2 | B4: GASTO OPERACIONAL COMERCIAL | C4: 11695770 | D4: PROMOTORA SANDVILLE
A5: G2 | B5: GASTO OPERACIONAL COMERCIAL | C5: 25986435 | D5: PROMOTORA WESTVILLE
A6: Expr1 | B6: Expr2 | C6: SumaDeSumaDeVALOR | D6: EMPRESA
A7: G3 | B7: COMISIONES COMERCIAL | C7: 38797886 | D7: PROMOTORA SANDVILLE
A8: G3 | B8: COMISIONES COMERCIAL | C8: 18653528 | D8: PROMOTORA WESTVILLE
A9: G3 | B9: COMISIONES COMERCIAL | C9: 2626862 | D9: PROMOTORA SANDVILLE
A10: G3 | B10: COMISIONES COMERCIAL | C10: 1464536 | D10: PROMOTORA WESTVILLE
A11: Expr1 | B11: Expr2 | C11: SumaDeSumaDeVALOR | D11: EMPRESA
A12: G4 | B12: NOMINA ADMINISTRACION | C12: 38812609 | D12: PROMOTORA SANDVILLE
A13: G4 | B13: NOMINA ADMINISTRACION | C13: 5264662 | D13: PROMOTORA WESTVILLE
A14: Expr1 | B14: Expr2 | C14: SumaDeSumaDeVALOR | D14: EMPRESA
A15: G5 | B15: GASTO OPERACIONAL ADMINISTRACION | C15: 60780515 | D15: PROMOTORA SANDVILLE
A16: G5 | B16: GASTO OPERACIONAL ADMINISTRACION | C16: 13322861 | D16: PROMOTORA WESTVILLE
A17: G5 | B17: GASTO OPERACIONAL ADMINISTRACION | C17: 610251 | D17: STATUS COMERCIALIZADORA
A18: Expr1 | B18: Expr2 | C18: SumaDeSumaDeVALOR | D18: EMPRESA
A19: G6 | B19: NOMINA CARTERA | C19: 7163476 | D19: PROMOTORA SANDVILLE
A20: G6 | B20: NOMINA CARTERA | C20: 1995604 | D20: STATUS COMERCIALIZADORA
A21: Expr1 | B21: Expr2 | C21: SumaDeSumaDeVALOR | D21: EMPRESA
A22: G7 | B22: GASTO OPERACIONAL CARTERA | C22: 3143481 | D22: PROMOTORA SANDVILLE
A23: G7 | B23: GASTO OPERACIONAL CARTERA | C23: 1146460 | D23: PROMOTORA WESTVILLE
A24: Expr1 | B24: Expr2 | C24: SumaDeSumaDeVALOR | D24: EMPRESA
A25: G8 | B25: NOMINA PROYECTOS | C25: 22236026 | D25: QUADRATA CONSTRUCTORES
A26: Expr1 | B26: Expr2 | C26: SumaDeSumaDeVALOR | D26: EMPRESA
A27: G9 | B27: GASTO OPERACIONAL PROYECTOS | C27: 5972925 | D27: QUADRATA CONSTRUCTORES
A28: Expr1 | B28: Expr2 | C28: SumaDeSumaDeVALOR | D28: EMPRESA | E28: PROYECTO
A29: G10 | B29: GASTO OBRA CLUB | C29: 353000 | D29: QUADRATA CONSTRUCTORES | E29: SANDVILLE
A30: Expr1 | B30: Expr2 | C30: SumaDeSumaDeVALOR | D30: EMPRESA | E30: PROYECTO
A31: G11 | B31: GASTO OBRA CONDOMINIO | C31: 25317744 | D31: QUADRATA CONSTRUCTORES | E31: SANDVILLE BEACH
A32: Expr1 | B32: Expr2 | C32: SumaDeSumaDeVALOR | D32: EMPRESA | E32: PROYECTO
A33: G12 | B33: ANTICIPOS OBRA | C33: 127913653 | D33: QUADRATA CONSTRUCTORES | E33: SANDVILLE
A34: G12 | B34: ANTICIPOS OBRA | C34: 7850716 | D34: QUADRATA CONSTRUCTORES | E34: RANCHO MONTANA
A35: Expr1 | B35: Expr2 | C35: SumaDeSumaDeVALOR | D35: EMPRESA | E35: PROYECTO
A36: G13 | B36: NOMINA CARTERA | C36: 20000000 | D36: PROMOTORA SANDVILLE | E36: SANDVILLE BEACH
A37: G13 | B37: NOMINA CARTERA | C37: 6413084 | D37: PROMOTORA WESTVILLE | E37: WESTIVILLE
A38: G13 | B38: NOMINA CARTERA | C38: 50000000 | D38: QUADRATA CONSTRUCTORES | E38: RANCHO MONTANA

Sheet CONFIG
G1: ASINGACION DE % POR CC | H1: SANDVILLE BEACH | I1: SANDVILLE DEL MAR | J1: SANDVILLE DEL SOL | K1: MIRADOR DE WESTVILLE
B2: EMPRESA | G2: SALARIOS COMERCIALES | H2: 0 | I2: 0 | J2: 0 | K2: 1
A3: OFICINA | B3: SANDVILLE | C3: WESTVILLE | D3: STATUS | G3: GASTO OPERACIÓN COMERCIAL | H3: 0.5 | I3: 0.5
A4: MONTERIA | B4: 1 | G4: GASTO ADMINISTRATIVO | H4: 0.33 | I4: 0.33 | J4: 0.33
A5: MEDELLIN | B5: 2 | C5: 1 | D5: 1 | G5: GASTO ADMIN PROYECTOS | H5: 1 | I5: 0 | J5: 0 | K5: 0
A6: SINCELEJO | B6: 3 | G6: SALARIOS CARTERA | H6: 0.25 | I6: 0.25 | J6: 0.25 | K6: 0.25

Sheet GastosHistorico
A1: Fecha | B1: Comprobante | C1: Cuenta | D1: Descripcion Cuenta | E1: Tercero | F1: Descripcion Gasto | G1: Item | H1: Valor | I1: Empresa

Sheet Control
A1: Sandville Beach | B1: 0 | C1: 0 | D1: 0 | F1: % Ventas Total | G1: =+'RESULTADOS MES'!E8 -> 0 | H1: =+'RESULTADOS MES'!I8 -> 0
A2: Sandville del Mar | B2: 0 | C2: 0 | D2: 0 | F2: % Ventas Procesables | G2: =+'RESULTADOS MES'!E5 -> 0 | H2: =+'RESULTADOS MES'!I5 -> 0
A3: Sandville del Sol | B3: 0 | C3: 0 | D3: 0 | F3: % Recaudo Ventas | G3: =+'RESULTADOS MES'!E12 -> 0 | H3: =+'RESULTADOS MES'!I12 -> 0
A4: Tesoro Escondido | B4: 20 | C4: 0.1 | D4: 0.1 | F4: % Recaudo Comercial | G4: =+'RESULTADOS MES'!D36 -> 0 | H4: =+'RESULTADOS MES'!J36 -> 0
A5: Vegas de Venecia | B5: 17 | C5: 0.1 | D5: 0.05 | F5: % Recaudo Administrativo | G5: =+'RESULTADOS MES'!D51 -> 0 | H5: =+'RESULTADOS MES'!J51 -> 0
F6: % Recaudo Cartera | G6: =+G4+G5 -> 0 | H6: =+H4+H5 -> 0
F7: % Recaudo Total | G7: =+G3+G6 -> 0 | H7: =+H3+H6 -> 0
F8: % Presupuestado
